Workbook

Sheet Sommaire
B1: SOMMAIRE DES FICHES REFLEXES
B4: INFORMATIONS UTILES
B7: 1 | C7: N° UTILES
B9: 2 | C9: Tableau Titulaires & Back up des personnes formées aux fiches réflexes
B11: 3 | C11: N° UTILES
B13: INCENDIE
A16: Obligatoire - A adapter localement | B16: 1 | C16: Scénario : incendie déclaré au sein de l'entrepôt ou des bureaux pendant les heures d'activité
B18: 2 | C18: Scénario : incendie déclaré au sein de l'entrepôt ou des bureaux hors des heures ouvrées
B20: 3 | C20: Scénario : à définir si besoin
B22: PANNE INFORMATIQUE
A25: Obligatoire - A adapter localement | B25: 1 | C25: Scénario : système informatique ID Logistics hors fonction
B27: 2 | C27: Scénario : système informatique Client hors fonction
B29: PANNE ELECTRIQUE
A32: Obligatoire - A adapter localement | B32: 1 | C32: Scénario : Rupture alimentation générale publique
B34: 2 | C34: Scénario : Rupture alimentation générale du site
B36: INONDATION
A39: Obligatoire - A adapter localement | B39: 1 | C39: Scénario : rupture canalisation eau potable
B41: 2 | C41: Scénario : rupture canalisation sprinkler ou RIA
B43: 3 | C43: Scénario : montée des eaux par les regards
A45: Facultatif | B45: 4 | C45: Scénario : Fuite
B47: CANICULE
A50: Obligatoire - A adapter localement | B50: 1 | C50: Scénario : T°intérieure > 30° C
B52: 2 | C52: Scénario : T°intérieure > 35° C
B55: GRAND FROID
A58: Obligatoire - non modifiables | B58: 1 | C58: Scénario : T°intérieure = 0°C
B60: 2 | C60: Scénario : T° intérieure < -5°C
B62: BLESSE
A65: Facultatif - A adapter localement | B65: 1 | C65: Scénario : Blessures légères sans conséquence sur l’activité du salarié
B67: 2 | C67: Scénario : Blessures non négligeables / Malaise nécessitant l'intervention des secours
B69: 3 | C69: Scénario : Malaise Cardiaque avec intervention des services de secours 2 cas : sans décès - avec décès
A71: Facultatif - A définir / adapter localement en fonction des besoins | B71: AUTRES SITUATIONS
B74: 1 | C74: Scénario : Nuisibles
B76: 2 | C76: Scénario : Incident palettier
B78: 3 | C78: Scénario : PRD
B80: 4 | C80: Scénario : Mise Hors/en service de l'installation sprinkler
A82: Obligatoire pour les sites soumis à POI | B82: POI
B85: 1 | C85: Scénario : vanne gaz
B87: 2 | C87: Scénario : TGBT
B89: 3 | C89: Scénario : Vanne guillotine

Sheet N° Utiles
C8: Site : | E8: Activité : | H8: MAJ :
C11: NUMEROS D'URGENCE
C13: Police | H13: 17
C14: Pompiers | H14: 18
C15: GENDARMERIE
C16: Samu
C17: SOS Mains et Doigts
C18: Centre anti poison
C19: Centre Grands Brulés
C21: NUMEROS PRATIQUE
C23: Ambulance
C24: Douanes
C25: D.D.E.
C26: Electricité
C27: Hôpital
C28: Inspection du travail
... C45: Electricité

Sheet Garant+back up
G1: Site de XXXXXXX
G2: Activité CARREFOUR
B3: FICHE REFLEXE | C3: Titulaire | E3: Back up # 1 | G3: Back up # 2
C4: NOM Prénom | D4: Fonction | E4: NOM Prénom | F4: Fonction | G4: NOM Prénom | H4: Fonction
A5: 1 | B5: FICHE REFLEXE - INCENDIE | C5: Fabien Watterlot | D5: Resp Site | E5: Mohammed Ayad | F5: Resp Expl | G5: / | H5: /
A6: 2 | B6: FICHE REFLEXE - PANNE INFORMATIQUE | G6: / | H6: /
A7: 3 | B7: FICHE REFLEXE - COUPURE ELECTRIQUE | G7: / | H7: /
A8: 4 | B8: FICHE REFLEXE - INNONDATION | G8: / | H8: /
A9: 1 | B9: FICHE REFLEXE - CANICULE | G9: / | H9: /
A10: 2 | B10: FICHE REFLEXE - GRAND FROID | G10: / | H10: /
A11: 3 | B11: FICHE REFLEXE - BLESSE | G11: / | H11: /
A12: 4 | B12: FICHE REFLEXE - AUTRE SITUATION | G12: / | H12: /

Sheet Fiche individuelle
B2: ATTESTATION DE FORMATION FICHE REFLEXE | F2: ='N° Utiles'!C9 -> 0
F4: ='N° Utiles'!E9:F9 -> 0
A9: Acte N° | C9: 2
A11: Désignation | C11: =INDEX('Garant+back up'!$B$5:$B$12,$C$9,1) -> FICHE REFLEXE - PANNE INFORMATIQUE
A13: Description | C13: =INDEX('Garant+back up'!A5:H12,C9,3) -> 0
A21: TITULAIRE
A22: NOM Prénom | E22: Fonction
A23: =INDEX('Garant+back up'!$A$5:$H$17,$C$9,4) -> 0 | E23: =INDEX('Garant+back up'!$A$5:$H$12,$C$9,5) -> 0
A25: Je, soussigné Nous, soussignés | C25: =A23 -> 0
A27: certifie / certifions sur l'honneur avoir formé le(s) back up
A28: à la réalisation de la fiche reflexe n° | F28: =$C$9 -> 2
D30: Signature
A33: BACK UP #1
A34: NOM Prénom | E34: Fonction
A35: =INDEX('Garant+back up'!$A$5:$H$17,$C$9,6) -> 0 | E35: =INDEX('Garant+back up'!$A$5:$H$17,$C$9,7) -> /
A37: Je, soussigné Nous, soussignés | C37: =A35 -> 0
A38: certifie / certifions sur l'honneur
A39: avoir été formé(s) le __ / __ / ____ | D39: à la réalisation de la fiche reflexe n° | G39: =$C$9 -> 2
A40: en qualité de remplaçant.
D41: Signature(s)
A44: BACK UP #2
A45: NOM Prénom | E45: Fonction
A46: =INDEX('Garant+back up'!$A$5:$H$17,$C$9,8) -> / | E46: =INDEX('Garant+back up'!$A$5:$H$12,$C$9,9) -> #REF!
A48: Je, soussigné | C48: =A46 -> / | F48: certifie sur l'honneur
A49: avoir été formé le __ / __ / ____ | D49: à la réalisation de l'acte n° | G49: =$C$9 -> 2
A50: en qualité de remplaçant.
D51: Signature
A54: VISA DU RESPONSABLE DE SITE

Sheet Trombi EVAC
A1: MATIN + APRES-MIDI | S1: Cellules:
A3: EVACUATION | S3: INCENDIE
A5: GUIDE-FILE | I5: SERRE-FILE | S5: Equipier Première Intervention
D7: Prénom + Nom: | L7: Prénom + Nom: | X7: Prénom + Nom:
D8: Titre: | L8: Titre: | X8: Titre:
D9: Service: | L9: Service: | X9: Service:
D10: Téléphone: | L10: Téléphone: | X10: Téléphone:
D11: Horaire: | F11: - | L11: Horaire: | N11: - | X11: Horaire: | AA11: -
F12: - | N12: - | AA12: -
D14: Prénom + Nom: | L14: Prénom + Nom: | X14: Prénom + Nom:
D15: Titre: | L15: Titre: | X15: Titre:
D16: Service: | L16: Service: | X16: Service:
D17: Téléphone: | L17: Téléphone: | X17: Téléphone:
D18: Horaire: | F18: - | L18: Horaire: | N18: - | X18: Horaire: | AA18: -
F19: - | N19: - | AA19: -
A21: BACK-UP | S21: BACK-UP
D23: Prénom + Nom: | L23: Prénom + Nom: | X23: Prénom + Nom:
D24: Titre: | L24: Titre: | X24: Titre:
D25: Service: | L25: Service: | X25: Service:
D26: Téléphone: | L26: Téléphone: | X26: Téléphone:
D27: Horaire: | F27: - | L27: Horaire: | N27: - | X27: Horaire: | AA27: -
F28: - | N28: - | AA28: -
D30: Prénom + Nom: | L30: Prénom + Nom: | X30: Prénom + Nom:
D31: Titre: | L31: Titre: | X31: Titre:
D32: Service: | L32: Service: | X32: Service:
D33: Téléphone: | L33: Téléphone: | X33: Téléphone:
D34: Horaire: | F34: - | L34: Horaire: | N34: - | X34: Horaire: | AA34: -
F35: - | N35: - | AA35: -

Sheet Trombi SST HOBE
A1: PREMIERS SECOURS
A2: Titulaire
A4: MATIN | I4: APRES-MIDI | Q4: NUIT
D6: Prénom + Nom: | L6: Prénom + Nom: | T6: Prénom + Nom:
D7: Titre: | L7: Titre: | T7: Titre:
D8: Service: | L8: Service: | T8: Service:
D9: Téléphone: | L9: Téléphone: | T9: Téléphone:
D10: Horaire: | F10: - | L10: Horaire: | N10: - | T10: Horaire: | V10: -
F11: - | N11: - | V11: -
D13: Prénom + Nom: | L13: Prénom + Nom: | T13: Prénom + Nom:
D14: Titre: | L14: Titre: | T14: Titre:
D15: Service: | L15: Service: | T15: Service:
D16: Téléphone: | L16: Téléphone: | T16: Téléphone:
D17: Horaire: | F17: - | L17: Horaire: | N17: - | T17: Horaire: | V17: -
F18: - | N18: - | V18: -
A20: BACK-UP
D22: Prénom + Nom: | L22: Prénom + Nom: | T22: Prénom + Nom:
D23: Titre: | L23: Titre: | T23: Titre:
D24: Service: | L24: Service: | T24: Service:
D25: Téléphone: | L25: Téléphone: | T25: Téléphone:
D26: Horaire: | F26: - | L26: Horaire: | N26: - | T26: Horaire: | V26: -
F27: - | N27: - | V27: -
D29: Prénom + Nom: | L29: Prénom + Nom: | T29: Prénom + Nom:
D30: Titre: | L30: Titre: | T30: Titre:
D31: Service: | L31: Service: | T31: Service:
D32: Téléphone: | L32: Téléphone: | T32: Téléphone:
D33: Horaire: | F33: - | L33: Horaire: | N33: - | T33: Horaire: | V33: -
F34: - | N34: - | V34: -
A36: HOBE
A37: Titulaire
A39: MATIN | I39: APRES-MIDI | Q39: NUIT
D41: Prénom + Nom: | L41: Prénom + Nom: | T41: Prénom + Nom:
D42: Titre: | L42: Titre: | T42: Titre:
D43: Service: | L43: Service: | T43: Service:
D44: Téléphone: | L44: Téléphone: | T44: Téléphone:
D45: Horaire: | F45: - | L45: Horaire: | N45: - | T45: Horaire: | V45: -
F46: - | N46: - | V46: -
A48: BACK-UP
D50: Prénom + Nom: | L50: Prénom + Nom: | T50: Prénom + Nom:
D51: Titre: | L51: Titre: | T51: Titre:
...

Sheet FR Incendie
D3: FICHE REFLEXE
B7: Site : | C7: ='N° Utiles'!$C$9 -> 0 | E7: Activité : | F7: ='N° Utiles'!$E$9 -> 0 | J7: MAJ le : | M7: ='N° Utiles'!$H$9 -> 0
B9: INCENDIE | M9: Page 1/2
C11: Scénario : incendie déclaré au sein de l'entrepôt ou des bureaux pendant les heures d'activité
C14: INCENDIE :
C16: ETAPES | E16: QUOI ? | J16: OU ? | M16: QUI ?
C17: 1 | E17: Intervenir si possible pour attaquer le feu à l'aide des extincteurs (et des RIA si le personnel est égament formé à leur utilisation). | M17: Le personnel formé EPI
C23: 2
E24: Si le feu est trop important Donner l'alerte : Contacter les pompiers au 18 ou 112. Indiquer l'endroit exact de l'incendie et son importance. Appuyer sur les déclencheurs manuels de l'alarme incendie | M24: Resp service ou chef d'équipe
M26: Resp service ou chef d'équipe
J27: Près des issues de secours
C29: 3
E30: EVACUER : Avant de quitter les locaux, fermer toutes les issues (fenêtres et portes / portes de quai). Récupérer le registre de sécurité (et autres documents, ex : plans, consignes...). Récupérer les feuilles de pointage Suivre les indications du Guide File pour sortir, et rejoindre le point de rassemblement situé à l’extérieur (près du portillon de l'entrée). | M30: Les Guide-files, les serre-files et le responsable d'évacuation
E34: NE JAMAIS REVENIR EN ARRIERE
C36: 4
E37: Au point de rassemblement, se ranger par service Faire l'appel | M37: Le personnel
M40: Resp service ou CE
C42: 5
E43: Prévenir le client | J43: Téléphone :
M44: Responsable d'évacuation
J45: 06 -xx-xx-xx-xx
C48: 6 | J48: Lors de leur arrivée sur site
E49: Laisser l'accès libre aux véhicules de secours Interdire l'accès à tout autre véhicule. Accueillir les secours et leur rendre compte des actions mises en œuvre, et le résultat du recensement des personnes évacuées
M50: Responsable d'évacuation
D56: FICHE REFLEXE
B60: Site : | C60: ='N° Utiles'!$C$9 -> 0 | E60: Activité : | F60: ='N° Utiles'!$E$9 -> 0 | J60: MAJ le : | M60: ='N° Utiles'!$H$9 -> 0
B62: INCENDIE | M62: Page 2/2
C64: Scénario : incendie déclaré au sein de l'entrepôt ou des bureaux hors des heures ouvrées
C67: INCENDIE :
C69: ETAPES | E69: QUOI ? | J69: OU ? | M69: QUI ?
C70: 1 | E70: Après report d'alarme, effectuer la levée de doute | M70: Société télésurveillance
J72: A définir
C76: 2
E77: S'il s'agit d'une alarme incendie, appeler immédiatement les sapeurs-pompiers Appeler le responsable de site et le client | M77: Société télésurveillance
J78: Tel resp: 06-xx-xx-xx-xx Tel client: 06-xx-xx-xx-xx
C80: 3
E81: Laisser l'accès libre aux véhicules de secours. Interdire l'accès à tout autre véhicule. | M81: Société télésurveillance
C86: 4
E87: Désactiver l'ensemble des alarmes, se positionner à l'entrée du site pour pouvoir guider les secours à leur arrivée. | M87: Société télésurveillance
J88: Poste de Garde A redéfinir

Sheet FR Informatique
D3: FICHE REFLEXE
B7: Site : | C7: ='N° Utiles'!$C$9 -> 0 | E7: Activité : | F7: ='N° Utiles'!$E$9 -> 0 | J7: MAJ le : | M7: ='N° Utiles'!$H$9 -> 0
B9: PANNE INFORMATIQUE | M9: Page 1/2
C11: Scénario 1: Système informatique ID Logistics hors fonction
C14: PANNE INFORMATIQUE : Panne INFOLOG
C16: ETAPES | E16: QUOI ? | J16: OU ? | M16: QUI ?
C17: 1 | E17: Vérifier que tous les voyants de la baie de brassage sont au "vert". | M17: Utilisateur des applications
C23: 2
E24: Vérifier au niveau de l’armoire informatique, la présence de voyants verts, lumineux | J24: Baie dans le hall à coté du couloir des vestiaires | M24: Responsable de service ou chef d'équipe
C29: 3
E30: Vérifier que la centrale est sous tension : Le voyant de la centrale doit être allumé et vert. Le cas échéant, remetre sous tension la centrale en appuyant sur le bouton veille. | J30: Local informatique situé au RDC | M30: Responsable de service ou chef d'équipe
D38: FICHE REFLEXE
B42: Site : | C42: ='N° Utiles'!$C$9 -> 0 | E42: Activité : | F42: ='N° Utiles'!$E$9 -> 0 | J42: MAJ le : | M42: ='N° Utiles'!$H$9 -> 0
B44: PANNE INFORMATIQUE | M44: Page 2/2
C46: Scénario 2 : Système informatique Client hors fonction
C49: PANNE INFORMATIQUE : Panne INFOLOG
C51: ETAPES | E51: QUOI ? | J51: OU ? | M51: QUI ?
C52: 1 | E52: Vérifier l'accès aux applications du Client (MDEPOT) | M52: Utilisateur des applications
C58: 2
E59: Vérifier au niveau de l’armoire informatique, la présence de voyants verts, lumineux | J59: A localiser | M59: Responsable de service ou chef d'équipe
C64: 3
E65: Arrêter puis remettre en route le routeur à l’aide de l’interrupteur Marche/Arrêt | J65: A localiser | M65: Responsable de service ou chef d'équipe
C70: 4
E71: si cela ne fonctionne toujours pas,contacter directement la HOTLINE du WMS | J71: TEL : | M71: Responsable de service ou chef d'équipe
J72: 06-xx-xx-xx-xx

Sheet FR COUPURE ELEC
D3: FICHE REFLEXE
B7: Site : | C7: ='N° Utiles'!$C$9 -> 0 | E7: Activité : | F7: ='N° Utiles'!$E$9 -> 0 | J7: MAJ le : | M7: ='N° Utiles'!$H$9 -> 0
B9: COUPURE ELECTIQUE | M9: Page 1/2
C11: Scénario 1 : Rupture de l'alimentation Générale Publique
C14: Ne jamais toucher aux disjoncteurs si vous n'êtes pas habilité. Seules les personnes formées peuvent ouvrir les armoires électriques et accéder au TGBT (Salle de charge). La clef du TGBT est dans le bureau de l'assistante.
C16: COUPURE ELECTRIQUE : COUPURE GENERALE PUBLIQUE
C18: ETAPES | E18: QUOI ? | J18: OU ? | M18: QUI ?
C19: 1 | E19: Téléphoner à EDF : xxxxx N° de contrat : xxxxxx | J19: Télephone fixe ou mobile | M19: Assistante du site
C25: 2
E26: Si la coupure est prévue d'être supérieure à 4h00, téléphoner pour louer un groupe electrogène : xxxxxx: Tel xxxxx Puissance du groupe requise : xxKVA | M26: Assistante du site
J27: Télephone fixe ou mobile
C31: 3
E32: Définir un emplacement pour positionner le groupe et libérer la place et les accès pour sa livraison. | J32: Salle de charge pour être au plus prés du TGBT | M32: Responsable de service ou Agent de maintenance
C37: 4
E38: Téléphoner aux agents de maintenance et à l'électricien pour branchement du groupe. | J38: Tel : XX XX XX XX XX
M39: Responsable de service ou Agent de maintenance
C43: 5
E44: Remonter le disjoncteur Principal
J45: TGBT | M45: Personnel Habilité H0B0
C49: 6
E50: Informer le client
J51: Tel | M51: Responsable de site
C55: 7
E56: Contrôle de l’installation par l'électricien EDF | J56: Tel : | M56: Responsable de site
D66: FICHE REFLEXE
B70: Site : | C70: ='N° Utiles'!$C$9 -> 0 | E70: Activité : | F70: ='N° Utiles'!$E$9 -> 0 | J70: MAJ le : | M70: ='N° Utiles'!$H$9 -> 0
B72: COUPURE ELECTIQUE | M72: Page 2/2
C74: Scénario 2 : Disjonction alimentation Générale du site
C77: Ne jamais toucher aux disjoncteurs si vous n'êtes pas habilité. Seules les personnes formées peuvent ouvrir les armoires électriques et accéder au TGBT (Salle de charge). La clef du TGBT est dans le bureau de l'assistante.
C79: COUPURE ELECTRIQUE : COUPURE GENERALE PUBLIQUE
C81: ETAPES | E81: QUOI ? | J81: OU ? | M81: QUI ?
C82: 1 | E82: Remonter le disjoncteur Principal | M82: Personnel Habilité H0B0
J84: TGBT
C88: 2
E89: Informer le client | M89: Responsable de site
J90: Nom : Tel :
C95: 4
E96: Contrôle de l’installation par l'éléctricien EDF | J96: Tel :
M97: Responsable de site

Sheet FR INONDATION
D3: FICHE REFLEXE
B7: Site : | C7: ='N° Utiles'!$C$9 -> 0 | E7: Activité : | F7: ='N° Utiles'!$E$9 -> 0 | J7: MAJ le : | M7: ='N° Utiles'!$H$9 -> 0
B9: INONDATION | M9: Page 1/4
C11: Scénario : Rupture de canalisation d'eau potable
C14: INONDATION
C16: ETAPES | E16: QUOI ? | J16: OU ? | M16: QUI ?
C17: 1 | E17: Couper l'alimentation principale d'eau en tournant la vanne Noir. | J17: A localiser | M17: Métro/Resp/ site /Rex/RS
C23: 2
E24: Mettre en sécurité les armoires électriques | J24: A localiser | M24: Métro/Resp/ site /Rex/RS
C29: 3
E30: Evacuer l'eau à l'aide des autos laveuses par pompage et de raclette. | J30: Télephone fixe ou mobile | M30: Personnel et Société de nettoyage.
C35: 4
E36: Prévenir le client | J36: Tel : | M36: Responsable du site
D45: FICHE REFLEXE
B49: Site : | C49: ='N° Utiles'!$C$9 -> 0 | E49: Activité : | F49: ='N° Utiles'!$E$9 -> 0 | J49: MAJ le : | M49: ='N° Utiles'!$H$9 -> 0
B51: INONDATION | M51: Page 2/4
C53: Scénario : Rupture de canalisation d'eau potable
C56: INONDATION
C58: ETAPES | E58: QUOI ? | J58: OU ? | M58: QUI ?
C59: 1 | E59: Mettre en sécurité les armoires électriques | J59: A localiser | M59: Métro/Resp/ site /Rex/RS
C65: 2
E66: Fermer toutes les vannes du poste sprinkler. Les clefs sont au poste de garde. | J66: A localiser | M66: Métro/Resp/ site /Rex/RS
C71: 3
E72: Evacuer l'eau à l'aide des autos laveuses par pompage et de raclette. | J72: Télephone fixe ou mobile | M72: Personnel et Société de nettoyage.
C77: 4
E78: Prévenir le client | J78: Tel | M78: Responsable du site
D87: FICHE REFLEXE
B91: Site : | C91: ='N° Utiles'!$C$9 -> 0 | E91: Activité : | F91: ='N° Utiles'!$E$9 -> 0 | J91: MAJ le : | M91: ='N° Utiles'!$H$9 -> 0
B93: INONDATION | M93: Page 3/4
C95: Scénario : Monté des eaux par les regards
C98: INONDATION
C100: ETAPES | E100: QUOI ? | J100: OU ? | M100: QUI ?
C101: 1 | E101: Mettre en sécurité les armoires électriques | J101: A localiser | M101: Métro/Resp/ site /Rex/RS
C107: 2
E108: Fermer toutes les vannes du poste sprinkler. Les clefs sont au poste de garde. | J108: A localiser | M108: Métro/Resp/ site /Rex/RS
C113: 3
E114: Evacuer l'eau à l'aide des autos laveuses par pompage et de raclette. | J114: Télephone fixe ou mobile | M114: Personnel et Société de nettoyage.
C119: 4
E120: Prévenir le client | J120: Tel : | M120: Responsable du site
D129: FICHE REFLEXE
...

Sheet FR_Problème_température_S_2
B2: FICHE REFLEXE
B10: Site : | C10: ='N° Utiles'!C9 -> 0 | E10: Activité : | F10: ='N° Utiles'!$E$9 -> 0 | G10: {='N° Utiles'!E9:F9} -> 0 | H10: 0 | J10: MAJ le : | K10: {='N° Utiles'!H9:I9} -> 0 | L10: 0
B12: Problème de température entrepôt | K12: Page 2/3
C16: Scénario 2 : constat de hausse (ou baisse) de la température sans dépassement des températures limitées.
C21: Problème Température
C23: ETAPES | E23: QUOI ? | I23: OU ? | K23: QUI ?
C25: 1 | E25: Téléphoner à XXXXXXX : | I25: XXXXXXXXXXX | K25: Directeur de site Responsable d'Exploitation Responsable Qualité Chef d'équipe Poste de garde
I35: Tout l'entrepôt
C36: 2 | E36: Fermeture des portes de quai | K36: Encadrement
C44: 3 | E44: Prévenir le client (Nom) | K44: Directeur de site Responsable d'Exploitation Responsable Qualité
I51: Indiquer le N°

Sheet FR_Problème_température_S_3
Q1: LA BREDE
B2: FICHE REFLEXE
B10: Site : | C10: 0 | E10: Activité : | F10: 0 | G10: 0 | H10: 0 | J10: MAJ le : | K10: 0 | L10: 0
B12: Problème de température entrepôt | L12: Page 3/3
C16: Scénario 3 : Problème de température persiste et la température est hors limite (+ ou - 2°C pendant 30 minutes).
C21: Problème T°
C23: ETAPES | E23: QUOI ? | I23: OU ? | L23: QUI ?
I29: N° Tel Mettre en copie du mail :
C30: 1 | L30: Responsable Exploitation Responsable qualité Responsable maintenance
E34: Prévenir le responsable du Site par téléphone et par mail
E49: Prise de température à cœur sur le produit le plus sensible toutes les 30 minutes | L49: Responsable de site / Responsable Exploitation / Responsable qualité
C50: 2
I51: Zone concernée
H61: N° de tel Adresses emails :
C62: 3 | E62: LOGO CLIENT En cas de températures non conformes, isoler la marchandise et prévenir le Client par téléphone et par mail
L63: Responsable Exploitation / Responsable qualité

Sheet FR_GRAND FROID
D3: FICHE REFLEXE
B7: Site : | C7: ='N° Utiles'!$C$9 -> 0 | E7: Activité : | F7: ='N° Utiles'!$E$9 -> 0 | J7: MAJ le : | M7: ='N° Utiles'!$H$9 -> 0
B9: GRAND FROID | M9: Page 1/2
C11: Scénario : La fiche réflexe est à utiliser dès que la température intérieure atteind le 0°C.
C14: GRAND FROID
C16: ETAPES | E16: QUOI ? | J16: OU ? | M16: QUI ?
C17: 1 | E17: Communiquer sur les risques | J17: Plasma et Briefs aux équipes | M17: Assistante Responsable de service ou chef d'équipe
C23: 2
E24: Doter le personnel de gants et bonnets | J24: Armoire des vétements de travail. | M24: Assistante ou Responsable sécurité
C29: 3
E30: A partir de -5°C, s'assurer que les pauses sont obligatoirement en zone tempérée. | J30: Salle chauffée exterieur ensoleillé | M30: Responsable de service ou chef d'équipe
C35: 4
E36: Procédure de fermeture des portes | M36: Responsable de service ou chef d'équipe
J37: Porte de quai
C41: 5
E42: Mettre à disposition des boissons chaudes gratuitement | J42: Salle chauffée | M42: Responsable de service ou chef d'équipe
C47: 6
E48: Achat de chauffages d'appoint | M48: Responsable maintenance
D56: FICHE REFLEXE
B60: Site : | C60: ='N° Utiles'!$C$9 -> 0 | E60: Activité : | F60: ='N° Utiles'!$E$9 -> 0 | J60: MAJ le : | M60: ='N° Utiles'!$H$9 -> 0
B62: GRAND FROID | M62: Page 2/2
C64: Recommandations INRS
C67: Des températures inférieures à 5 °C présentent un risque immédiat pour les travailleurs exposés. Mais la température ne suffit pas à caractériser un environnement froid. Des températures inférieures à 15 °C peuvent déjà, en fonction des individus, provoquer un inconfort à des postes sédentaires ou de pénibilité légère. La sensation de froid n’est pas strictement liée à la température mesurée. Elle peut être accentuée par différents facteurs comme le mouvement de l’air (vitesse du vent) et l’humidité. Ces différents paramètres, ainsi que la nature du travail et les effets de la dépense énergétique liée à sa réalisation, sont à prendre en compte pour évaluer les risques professionnels liés au froid.
C74: Effets du froid Fatigue accrue, perte de dextérité… Le froid peut avoir des répercussions sur la qualité du travail et provoquer directement ou indirectement des accidents (glissades…). Les effets sur la santé peuvent concerner le corps dans son ensemble ou seulement les parties exposées, des simples engourdissements jusqu’aux gelures. L’effet d’ordre général le plus sérieux est l’hypothermie. Elle survient lorsque l’individu ne parvient plus à réguler sa température interne. Ses conséquences peuvent s’avérer dramatiques : troubles de la conscience, coma, voire décès.
C76: Prévention Un certain nombre d’accidents et de troubles sont évitables si une prévention adaptée est mise en place. Les mesures les plus efficaces consistent à éviter ou à limiter le temps de travail au froid. À défaut, il convient, entre autres mesures, d’organiser le travail, de fournir des équipements de travail adaptés et d’aménager les locaux de pauses. Le salarié, qui doit être informé des risques qu’il encourt, peut également agir en adoptant une protection vestimentaire adéquate, en choisissant une alimentation adaptée ou encore en surveillant sa condition physique.

Sheet FR_CANICULE (2)
C3: FICHE REFLEXE
B11: Site : | F11: 0 | J11: MAJ le : | L11: 0
B14: CANICULE | K14: Page 1/2
C18: Scénario : La fiche reflexe est à utiliser dès que la température intérieure atteint les 30°C.
C23: CANICULE :
C25: ETAPES | E25: QUOI ? | I25: OU ? | K25: QUI ?
C27: 1 | D27: Information et sensibilisation des salariés sur les signes de stress thermiques (pâleur ou pâleur des gencives, respiration et pouls rapides, soif extrême, crampes musculaires, fatigue ou faiblesse, vertiges, maux de tête, nausée ou vomissements …) | I27: Performance Corner Ecran IOBEYA | K27: Responsable de site & Responsable de service
C30: 2 | D30: Doter les salariés de casquettes pour le travail en extérieur Retrait des gilets haute visibilité si nécessaire Port de vêtements respirants (tee shirt coton) | K30: Responsable de site & Responsable de service
C36: 3 | D36: Pauses encadrées en zones tempérées obligatoirement : brumisateur, ventilateur, climatisation … Possibilité de prévoir des pauses supplémentaires selon les postes de travail | K36: Responsable de site & Responsable de service
C39: 4 | D39: Adaptation des horaires de travail, si possible notamment pour le travail en extérieur, dans les conteneurs et la preparation de commande Mise à disposition de système de rafraichissement (ventilateur, brumisateur ...) dans les zones à forte chaleur comme conteneur, méca, mezza … | K39: Responsable de site & Responsable de service
C47: 5 | D47: Eau à disposition en permanence : Prévoir 3L par jour et par personne | K47: Responsable de site & Responsable de service
C54: 6 | D54: Surveillance renforcée des personnes vulnérables (femme enceinte, salarié atteint de pathologie chronique) Les collaborateurs concernés doivent en informer la direction du site pour la mise en place d'une surveillance renforcée | K54: Responsable de site & Responsable de service

Sheet FR_FOUDRE
B10: Site : | C10: ='N° Utiles'!$C$9 -> 0 | E10: Activité : | F10: ='N° Utiles'!$E$9 -> 0 | J10: MAJ le : | M10: ='N° Utiles'!$H$9 -> 0
B14: IMPACT FOUDRE | K14: Page 1/1
C18: Scénario : activité orageuse, impacts de foudre potentiels ou avérés
C22: FOUDRE
C24: Prestataire Foudre | E24: MR xxxxx | G24: T : xx xx xx xx xx | K24: mail
C26: Sur site doit exister un classeur "foudre". Sont classés : • Chaque modification ou additif sur les études initiales (Analyse du Risque Foudre et Etude Technique) ; • Toutes les vérifications périodiques réglementaires (la périodicité des visites doit y être également mentionnée) ; • Tous les travaux de protection contre la foudre ainsi que le motif de ces travaux ; • A chaque période d’activité orageuse doivent être ajoutées les fiches de contrôle de l’état des dispositifs de protection contre la foudre ; • L’historique des impacts foudre répertoriés sur le site.
C34: FOUDRE
C36: ETAPES | E36: QUOI ? | I36: OU ? | K36: QUI ?
C38: 1 | E38: Faire le tour de l'ensemble du bâtiment par l'extérieur, relever sur chaque compteur le nombre d'impacts
C45: 2 | E45: Noter le nombre d'impacts de chaque compteur sur la fiche de suivi
C52: 3 | E52: S'il y a un impact supplémentaire, contacter le prestataire pour effectuer un contrôle de l'installation | I52: N° xx xx xx xx xx
C57: 4 | E57: Après intervention du technicien, enregistrement sur le registre sécurité, archivage du bon d'intervention. En cas de non-conformité, réaliser demande de devis et planifier les travaux de remise en conformité

Sheet FR BLESSE PHARMACIE
D3: FICHE REFLEXE
B7: Site : | C7: La Brède | E7: Activité : | F7: Métro | J7: MAJ le : | M7: 46013
B9: BLESSE - PHARMACIE | M9: Page 1/1
C11: Scénario : Blessures légères sans conséquence sur l’activité du salarié ATTENTION LE SST NE DOIT INTERVENIR QUE S'IL NE MET PAS SA PROPRE VIE EN DANGER
C14: BLESSE PHARMACIE
C16: ETAPES | E16: QUOI ? | J16: OU ? | M16: QUI ?
C17: 1 | E17: Vous êtes témoin qu'un de vos collègues se blesse, faire prévenir un SST et un responsable | J17: Trombinoscope | M17: Tout témoin
C23: 2
E24: Soin sur place par un SST Utiliser l'une des pharmacies de l'entrepôt. Bien se désinfecter les mains, puis utiliser des gants jetables | M24: Personnel formé SST
C29: 3
E30: Prodiguer les soins nécessaires, si la blessure est trop importante se reporter aux consignes de la fiche réflexe ACCIDENT DU TRAVAIL. | M30: Personnel formé SST
C35: 4
E36: Remplir la fiche d'analyse préalable | M36: Resp Exploitation ou chef d'équipe
C41: 5
E42: Ramener le plus rapidement la Fiche d'analyse préalable à l'assistante | M42: Resp Exploitation ou chef d'équipe

Sheet FR BLESSE SECOURS
D3: FICHE REFLEXE
B7: Site : | C7: ='N° Utiles'!$C$9 -> 0 | E7: Activité : | F7: ='N° Utiles'!$E$9 -> 0 | J7: MAJ le : | M7: ='N° Utiles'!$H$9 -> 0
B9: BLESSE - PHARMACIE | M9: Page 1/1
C11: Scénario : Blessures non négligeables / Malaise nécessitant l'intervention des secours
C14: BLESSE SECOURS
C16: ETAPES | E16: QUOI ? | J16: OU ? | M16: QUI ?
C17: 1 | E17: Prévenir un Sauveteur Secouriste du travail en poste. | J17: Trombinoscope | M17: Tout témoin
C23: 2
E24: PROTEGER C’est reconnaître, sans s’exposer soi même, les risques persistants qui menacent la victime de l’accident et les autres personnes exposées.
C29: 3
E30: EXAMINER C'est faire un examen clair et précis de la victime (conscient : échange avec la victime si inconscient rechercher saignement, contusion, étouffement … afin de déterminer les actions à mener par ordre d'urgence | M30: Personnel formé SST
C35: 4
E36: ALERTER Constat de l'accident par le responsable, qui - avertit l'assistante - prévient les secours | M36: Responsable de site Responsable de service Chef d'équipe
J38: 18 PAR LE FIXE, 112 PAR LE PORTABLE
D41: NE JAMAIS RACCROCHER LE PREMIER, ENVOYER UNE PERSONNE POUR ACCUEILLIR LES SECOURS et LES DIRIGER
C43: 5
E44: SECOURIR Apporter les soins nécessaires à l’aide du matériel à disposition dans les trousses de premiers secours. | M44: Personnel formé SST
C49: 6
E50: Une fois les services de secours sur place, rendre compte de l'accident et des soins réalisés par le SST | M50: Responsable de site Responsable de service Chef d'équipe Personnel formé SST
C55: 7
E56: Remplir les volets de soins à remettre au salarié accidenté. Respecter la procédure Gestion des AT | M56: Assistante Reporting Site
C61: 8
E62: Ramener à l'assistante le plus rapidement l'ensemble des documents : - Analyse préalable - Décharge (si le salarié rentre par ses propres moyens) | M62: Responsable de site Responsable de service Chef d'équipe Personnel formé SST

Sheet FR MALAISE CARDIAQUE
D3: FICHE REFLEXE
B7: Site : | C7: ='N° Utiles'!$C$9 -> 0 | E7: Activité : | F7: ='N° Utiles'!$E$9 -> 0 | J7: MAJ le : | M7: ='N° Utiles'!$H$9 -> 0
B9: Malaise Cardiaque | M9: Page 1/1
C11: Scénario : MALAISE AVEC INTERVENTION SST et POMPIERS PROVOQUANT UN DECES
C14: MALAISE CARDIAQUE
C16: ETAPES | E16: QUOI ? | J16: OU ? | M16: QUI ?
C17: 1 | E17: Prévenir un Sauveteur Secouriste du travail en poste. | J17: Trombinoscope | M17: Tout témoin
C23: 2
E24: Appeler le samu au 15, prendre le nom du médecin et attendre ces instructions. | M24: Personne formée SST
C29: 3
E30: Aller chercher le défibrilateur | J30: En tour 1 près du bureau de préparation | M30: personne témoin / responsable de site/ chef d'équipe
C35: 4
E36: En attendant le défibrilateur : Réanimer la personne : | M36: Personne formée SST
E38: -Placer la victime sur un plan dur
E40: - Positionnez-vous bras tendus et compresser le sternum à 4 ou 5 cm
E43: - Effectuer 30 compressions thoraciques (environ 2 compressions par seconde)
E46: - Positionner la tête de de la victime vers l'arrière, soulever son menton et faite 2 insufflations.
E50: - Alterner 30 compressions thoraciques et 2 insufflations jusqu'à l'arrivée du défibrilateur
C55: 5
M56: Personne formée SST
E57: Utiliser le défibrilateur :
E59: - Placer les électrodes à même la peau conformément aux instructions figurant sur l'emballage
E65: - Assurez-vous que personne ne touche la victime lorsque le defibrilateur analyse son rythme cardiaque
E70: -Si un choc électrique doit être administré, assurez-vous que toutes les personnes présentes sont éloignées de la victime et de son environnement immédiat.
E79: -Appuyez sur le bouton si cela vous est demandé. Un défibrillateur entièrement automatique administrera le choc électrique sans votre intervention
E87: Si le Défibrilateur vous y invite, effectuez des compressions thoraciques sans tarder. Alternez les séries de 30 compressions et de 2 insufflations.
C97: 6
E98: Prise en charge de la victime | M98: Services de secours
C103: 7
E104: En cas de décès de la victime contacter : | M104: Assistante Reporting/ Responsable de site
J105: A indiquer
E106: Pompes Funèbres de : XXXXXXXXX
J107: A indiquer
C109: 8
E110: Informer le directeur des risques opérationnels, le DOP & le DOP Zone, le DRH, la responsable communication, pour déploiement de la cellule psychologie & communication officielle. | M110: Responsable de Site

Sheet FR CONSTAT DECES
D3: FICHE REFLEXE
B7: Site : | C7: ='N° Utiles'!$C$9 -> 0 | E7: Activité : | F7: ='N° Utiles'!$E$9 -> 0 | J7: MAJ le : | M7: {='N° Utiles'!H9:I9} -> 0 | N7: 0
B9: ACTIONS SUITE DECES | M9: Page 1/1
C11: Scénario : Vous venez d'être confronté à un décès sur votre site. Quelles sont les actions à engager ?
C14: Le collaborateur est décédé
C16: ETAPES | E16: QUOI ? | J16: COMMENT ? | M16: QUI ?
C17: 1 | E17: Prévenir le STAFF Régional de l'évènement. Priorité : prévenir le DOR qui fera suivre l'information à son STAFF régional | J17: Téléphone / mail | M17: Responsable de Site
C23: 2
E24: Prévenir les membres du CODIR : DG / DOP France / DRH France / Directeur SST France | J24: Téléphone / mail | M24: D.O.R.
C29: 3
E30: Prévenir les partenaires sociaux CSSCT et CSE et organiser si nécessaire une réunion extraordinaire | J30: Mail | M30: DRH Région
C35: 4 | E35: Prévenir l'inspection du travail dans les 12h après la connaissance d'un décès survenu sur le lieu du travail | J35: Sur site | M35: DRH Région
C39: 5 | E39: Réunir les documents suivants : VM, contrat de travail ou de mise à disposition, durée du travail/repos et productivité moyenne des semaines précédentes | J39: Sur site | M39: DRH Région
C42: 6 | E42: Prévenir l'employeur du collaborateur si ce collaborateur n'est pas un salarié ID (ex : agence d'intérim) | J42: Téléphone / mail | M42: Responsable de Site
C44: 7
E45: Informer le client afin que celui-ci ne soit pas informé par une source externe (ex : médias) | J45: Téléphone / mail | M45: Responsable de Site
C50: 8
E51: Prévenir les organismes publics compétents : Inspection du travail et médecine du travail + Mise en place d'une cellule psychologique | J51: Mail | M51: DRH Région
C56: 9
E57: Communiquer les coordonnées du salarié à la police / gendarmerie pour qu'ils puissent avertir la famille du défunt. Cela ne doit JAMAIS être fait par un membre de l'entreprise | J57: Mail | M57: Responsable de Site
C61: 10
E62: Contacter la mairie pour effectuer la prise en charge par les pompes funèbres si cette action n'est pas déclenchée par les secours présents. | M62: Responsable de Site
J64: Téléphone
C68: 11
E69: Réaliser la DAT sous le contrôle du Cabinet Facthory et en lien avec le Service Affaires Sociales ID | M69: Responsable de site DRH Région RQHSE
J70: Mail
C74: 12
E75: Informer le service communication du groupe | M75: D.O.R
J76: Téléphone / mail
C80: 13
E81: Récolter auprès des témoins et collaborateurs les informations "à chaud" afin de retracer le plus précisément possible le déroulé des évènements | M81: QHSE Région Management site SST site
J83: Document Arbre des causes
C86: 14
E87: Réaliser une communication le lendemain de l'évènement auprès des équipes. En fonction des horaires des shifts pour que tout le monde ait le même niveau d'information. | M87: Responsable de site
J89: Brief
C92: 15
E93: Récupérer les données du DEA si utilisé. Aucun document ne doit être communiqué sans validation préalable du DRH Région. Solliciter l'assist. sociale pour accompagner la famille sur les démarches. Contacter mutuelle / prévoyance pour déclenchement des aides éventuelles. | M93: Responsable de Site DRH Région
J95: Mail

Sheet FR_Intrusion
B11: Site : | C11: ='N° Utiles'!$C$9 -> 0 | E11: Activité : | F11: ='N° Utiles'!$E$9 -> 0 | J11: MAJ le : | M11: ='N° Utiles'!$H$9 -> 0
B14: Intrusion | K14: Page 1/1
C18: Scénario : Intrusion d'une personne menacante dans l'enceinte du site
C22: Intrusion :
C24: ETAPES | E24: QUOI ? | I24: OU ? | K24: QUI ?
C26: 1 | E26: Informer le premier encadrant si possible sinon, déclencher l’alerte spécifique « intrusion » prévue par le site (alarme/ PTI etc…) | K26: Personne témoin
C34: 2
K36: Encadrement ou témoin si l'encadrement n'a pas pu être informé
E42: 1ere solution: S'échapper si et seulement si : - Vous avez identifié la localisation exacte du danger - Vous êtes certain de pouvoir vous échapper sans risque avec les salariés -Restez Calme -Prendre la sortie la moins exposée et la plus proche -Utiliser un itinéraire connu -Demander le silence absolu
C43: 3 | K43: Tous
C48: 3 | E48: 2ème solution : S'enfermer, se barricader, se cacher -Verrouiller les portes si possible sinon rejoindre les locaux préidentifier les plus sûrs •Se barricader au moyen du mobilier identifié auparavant. • Éteindre les lumières. • S’éloigner des murs, portes et fenêtres. • S’allonger au sol derrière plusieurs obstacles solides. • Faire respecter le silence absolu (portables en mode silence, sans vibreur). • Rester proche des personnes manifestant un stress et les rassurer. • Attendre l’intervention des forces de l’ordre.
K49: Tous
C55: 4 | E55: Se conformer aux consignes des forces de l'ordre et faciliter l'action des secours : •N’évacuer les lieux que sur instruction des forces de l’ordre. •Laisser toutes les affaires sur place. •Évacuer calmement les mains levées et apparentes pour éviter d’être perçu comme un suspect. •Signaler les blessés et l’endroit où ils se trouvent.
K56: Tous
C62: 5
E63: Après l'incident : Donner l'acces au caméras aux force de l'ordre | K63: Encadrement
C69: 6 | E69: 1er cas : personne ayant commis l'intrusion a été arrété : •Prévenir la hierarchie opérationnelle : DOR / ROR / DOP France 2eme cas : personne ayant commis l'intrusion n'a pas été arreté : •Prévenir la hierarchie opérationnelle : DOR / ROR / DOP France • Doubler le gardiennage • Demander a la gendarmerie de realiser des rondes
K70: Encadrement

Sheet FR_NUISIBLES
D3: FICHE REFLEXE
B7: Site : | C7: ='N° Utiles'!$C$9 -> 0 | E7: Activité : | F7: ='N° Utiles'!$E$9 -> 0 | J7: MAJ le : | M7: ='N° Utiles'!$H$9 -> 0
B9: NUISIBLES | M9: Page 1/1
C11: Scénario : des nuisibles ou des traces de nuisibles sont découverts dans l'entrepôt (nuisibles : rongeurs, pigeons, chats, insectes volants ou rampants)
C14: BLESSE PHARMACIE
C16: ETAPES | E16: QUOI ? | J16: OU ? | M16: QUI ?
C17: 1 | E17: Avertir le chef d’équipe du site en donnant l’emplacement de la(es) palette(s) concernée(s), ou de la zone concernée. | M17: tout témoin
C23: 2
E24: Avertir le responsable de site / d'exploitation Si zone entrepôt : Isoler la(es) palette(s) du picking concerné, et la(es) déposer en zone anomalie, ou signaler la zone contaminée au Resp d'Expl ou Resp de Site | M24: Chef d'équipe ou Responsable de Service
C29: 3
E30: Vérifier ensemble la contamination des produits sur les pickings de l’allée et des allées voisines (traces de nuisibles, consommation des aliments…), ou la zone contaminée. | M30: Responsable GDS
C38: 4
M39: Responsable GDS
E40: Bloquer physiquement et informatiquement les palettes concernées et les mettre en zone anomalie. Vérifier les supports déjà préparés de cette référence (possibilité de les mettre en contrôle dirigé et/ou d'informer les magasins)
C56: 5
E57: Demander une intervention d’urgence au prestataire de lutte contre les nuisibles | M57: Resp d'exploitation / Responsable de Site
J59: RENTOKILL
C62: 6
E63: Ajout de pièges ou Traitement de fumigation / répulsif ou mise en place de Désinsectocuteurs… & surveillance régulière | M63: Prestataire Rentokill
J64: Sous 48 h
C68: 7
E69: En cas de rongeurs / pigeons / chats / insectes volants : Réparer, améliorer l’herméticité du bâtiment dans les plus brefs délais. En cas d'insectes rampants : Procéder au nettoyage / à la désinfection des équipements de locaux sociaux. | M69: Tous

Sheet FR_Effondrement_palettier
B1: =B1:M58 -> 0
B11: Site : | C11: ='N° Utiles'!$C$9 -> 0 | E11: Activité : | F11: ='N° Utiles'!$E$9 -> 0 | J11: MAJ le : 18/06/2025 | K11: {='N° Utiles'!H9:I9} -> 0 | L11: 0
B14: Incident Palettier | K14: Page 1/1
C18: Scénario 3 : Effondrement du palettier
C21: incident paletier :
C23: ETAPES | E23: QUOI ? | I23: OU ? | K23: QUI ?
C25: 1 | E25: Effondrement de montants du palettier, se positionner hors de porté du danger | I25: Près des quais ou en fond de cellule | K25: Témoin ou encadrement
C32: 2 | E32: Baliser la zone, isoler la cellule | H32: Zone de sécurité baliser avec les panneaux de balisages | K32: Responsable d'exploitation Resp. de Service Chef d'Equipe
C41: 3 | E41: Procéder à l'appel de l'ensemble du personnel, chauffeurs, visiteurs et intervenants | H41: Point de rassemblement | K41: Responsable d'exploitation Resp. de Service Chef d'Equipe
C47: 4 | E47: En cas de victime, prise en compte et geste de premiers secours par l'équipe STT. Appel des secours n° tel : 15 | H47: Sur les lieux | K47: Equipe SST
C54: 5 | E54: Prévenir la Direction du site | K54: Témoin ou encadrement

Sheet FR_INCIDENT_PALETTE_PALETTIER
D3: FICHE REFLEXE
B7: Site : | C7: ='N° Utiles'!$C$9 -> 0 | E7: Activité : | F7: ='N° Utiles'!$E$9 -> 0 | J7: MAJ le : | M7: ='N° Utiles'!$H$9 -> 0
B9: INCIDENT PALETTE - LISSE | M9: Page 1/1
C11: Scénario : palette ou lisse dangereuse dans le palettier
C14: INCIDENT PALETTIER
C16: ETAPES | E16: QUOI ? | J16: OU ? | M16: QUI ?
C17: 1 | E17: Palette ou lisse dangereuse se positionner hors de portée du danger | J17: A trois alvéoles de l'incident | M17: Témoin ou encadrement
C23: 2
E24: Remonter l'allée afin d'alerter et arrêter les déplacements, baliser la zone.S'assurer que l'allée adjacente ne soit pas dangereuse | J24: Zone de sécurité distante de trois alvéoles, baliser la zone | M24: Opérateur ou encadrement
C29: 3
E30: Faire intervenir une nacelle | M30: Personnel habilitée à la conduite de nacelle
J32: Zone dangereuse
C38: 4
M39: Encadrement
E40: Bloquer la marchandise ou l'emplacement informatiquement
J42: Bureau GDS, ou mail

Sheet FR_PRD
D3: FICHE REFLEXE
B7: Site : | C7: ='N° Utiles'!$C$9 -> 0 | E7: Activité : | F7: ='N° Utiles'!$E$9 -> 0 | J7: MAJ le : | M7: ='N° Utiles'!$H$9 -> 0
B9: INCIDENT PRD | M9: Page 1/2
C11: Scénario : PROJECTION de produits dangereux sur le personnel
C14: INCIDENT PALETTIER
C16: ETAPES | E16: QUOI ? | J16: OU ? | M16: QUI ?
C17: 1
E18: Prévenir un Sauveteur Secouriste du travail en poste. | J18: Trombinoscope | M18: Témoin
C26: 2 | E26: le salarié "victime" doit : se rincer abondamment la zone touchée pendant 15 MIN si touché aux YEUX utiliser le rince yeux ou douche (pour les rince oeil portatif utiliser la totalité du flacon) | M26: Avec l'aide du personnel SST (trombinoscope) ou témoin de l'accident
C32: 3
E33: si la victime est touchée sur une grande surface, placer la victime sous la douche portative et enlever tous les vétements, le cas échéant lire le FICHE DE SECURITE du produit | J33: SALLE DE CHARGE SE MUNIR DE GANTS pour éviter la contamination | M33: SST / encadrement ou temoin
C38: 4
E39: Alerter les secours : 15 SAMU ou 18 POMPIER | M39: SST / encadrement ou temoin
C47: 5
M48: Témoin ou encadrement
E49: En cas de dégagement toxique, aérer immédiatement ou actionner désenfumage
J50: Porte de quai
D62: FICHE REFLEXE
B66: Site : | C66: ='N° Utiles'!$C$9 -> 0 | E66: Activité : | F66: ='N° Utiles'!$E$9 -> 0 | J66: MAJ le : | M66: ='N° Utiles'!$H$9 -> 0
B68: INCIDENT PRD | M68: Page 2/2
C70: Scénario : PROJECTION de produits dangereux sur le personnel
C73: INCIDENT PALETTIER
C75: ETAPES | E75: QUOI ? | J75: OU ? | M75: QUI ?
C76: 1 | E76: FORTE EMANATION de produits dangereux : aérer immédiatement la zone, déclenchement du bouton poussoir ALARME et DESENFUMAGE | J76: Porte de quai ou bouton poussoir ou désenfumage pour aérer SORTIE DE SECOURS | M76: Personnel présent et encadrement SSIAP
C82: 2
E83: Ecoulement de produits dangereux sur le sol : baliser la zone de danger avec des plots et de la rubalise | J83: Zone concernée | M83: Opérateur ou encadrement
C88: 3
E89: Utiliser le KIT d'épandage (absorbant) produit dangereux afin de délimiter la zone infectée | J89: Situation des kits: A localiser | M89: Personne présente ou encadrement
C97: 4
M98: Responsables de service ou chefs d'équipe
E99: Prévenir le POSTE de securité
J104: Ajouter le N° de tel PC

Sheet FR_SPRINKLER
D3: FICHE REFLEXE
B7: Site : | C7: ='N° Utiles'!$C$9 -> 0 | E7: Activité : | F7: ='N° Utiles'!$E$9 -> 0 | J7: MAJ le : | M7: ='N° Utiles'!$H$9 -> 0
B9: MISE HORS / EN SERVICE INSTALLATION SPRINKLER | M9: Page 1/2
C11: Scénario : travaux sur l'installation ou fuite système, obligation de mise hors service. Une fois les réparations effectuées, remise en service.
C14: INCIDENT PALETTIER
C16: ETAPES | E16: QUOI ? | J16: OU ? | M16: QUI ?
C17: 1
E18: AVANT L'INTERVENTION DEFINIR : Délais avant mise hors service : - Dans les 12 heures pour un accident, un incident ou un sinistre. - 3 jours (72h) avant pour modification, extension ou entretien (ex : visite triennale…) La mise hors service de l’installation doit être validée par le propriétaire. Toute coupure sur réseau devra être justifiée par la transmission au PCS d'un formulaire N-100 rempli et signé par M. Peyrol (ou M. Da Costa) avant le début de l'opération. S'assurer qu'IDL ait reçu une copie de ce N-100 avant le commencement des travaux. La partie A du N-100 doit être complétée et signée par le responsable technique ITM M. Peyrol et par la société intervenante. Une fois le N-100 complété le remettre en : 1 exemplaire à l'intervenant, 1 pour le PCS, 1 exemplaire à transmettre à J.Peyrol (ITM) Conserver 1 exemplaire au PCS
J46: FAX / e.mail voir N° utiles & Annuaire IDL
C50: 2 | E50: Mise hors service de l'installation sprinkler complète ou de postes sprinklers | J50: A la centrale sprinkler dans le local sprinkler | M50: Prestataire référencé pour le site
C56: Précautions à prendre : Interdire les travaux par points chauds, prévoir une ronde de surveillance toutes les 2 heures la nuit (si besoin), prévoir un gardiennage permanent le week-end (si besoin). Les documents en attente de remise en service seront classés dans le registre sécurité. Un exemple de chaque document est disponible avec la fiche reflexe.
C62: 4
E63: Remise en service de toute l'installation sprinkler | M63: Prestataire référencé pour le site
J65: A la centrale sprinkler dans le local sprinkler
C71: 5
E73: APRES L'INTERVENTION : Compléter le document N100 : Faire remplir le cadre B par M. Peyrol et le faire signer par l'entreprise intervenante. Une fois le N-100 complété le remettre en : 1 exemplaire à l'intervenant, 1 pour le PCS, 1 exemplaire à transmettre à J.Peyrol (ITM) Conserver 1 exemplaire au PCS
J80: FAX / e.mail / adresses voir N° utiles & Annuaire IDL

Sheet FR_VANNE GAZ
D3: FICHE REFLEXE
B7: Site : | C7: ='N° Utiles'!$C$9 -> 0 | E7: Activité : | F7: ='N° Utiles'!$E$9 -> 0 | J7: MAJ le : | M7: ='N° Utiles'!$H$9 -> 0
B9: COUPURE VANNE DE GAZ | M9: Page 1/1
C11: Scénario : incendie déclaré au sein de l'entrepôt ou des bureaux
C14: GAZ: ARRET DES VANNES
C16: Assistant OI
C17: Back-up Assistant OI
C20: ETAPES | E20: QUOI ? | J20: OU ? | M20: QUI ?
C21: 1 | E21: Se rendre sur la zone | J21: Voir plan | M21: Assistant Opération Interne Personne désignée
C27: 2
E28: Briser la vitre en plastique | M28: Assistant Opération Interne Personne désignée
C33: 3
G34: Vanne Gaz en position ouverte | M34: Assistant Opération Interne Personne désignée
G38: A gauche pour fermeture
C42: 4
E43: Consigner l'évenement sur la main courante

Sheet FR- TGBT
D3: FICHE REFLEXE
B7: Site : | C7: ='N° Utiles'!$C$9 -> 0 | E7: Activité : | F7: ='N° Utiles'!$E$9 -> 0 | J7: MAJ le : | M7: ='N° Utiles'!$H$9 -> 0
B9: ARRET TGBT COUP DE POINT | M9: Page 1/1
C11: Scénario : incendie déclaré au sein de l'entrepôt ou des bureaux
C14: TGBT : ARRET COUP DE POING
C16: Assistant OI | E16: J.PEYROL | F16: Port : 06 73 17 54 28
C17: Back-up Assistant OI | E17: C. GROUARD | F17: Port : 06 71 83 00 96
C18: Ne jamais toucher aux disjoncteurs si vous n'êtes pas habilité. Seules les personnes formées peuvent ouvrir les armoires électriques et accéder au TGBT (extérieur). Les clefs des TGBT se trouvent au PCS.
C21: ETAPES | E21: QUOI ? | J21: OU ? | M21: QUI ?
C22: 1 | E22: Se rendre sur la zone | J22: Voir plan | M22: Assistant Opération Interne Personne désignée
C28: 2
E29: Déclencher le "coup de poing "des locaux TGBT TGBT 1, 2 et 3 : | M29: Assistant Opération Interne Personne désignée
C34: 4
E35: Consigner l'évenement sur la main courante
J37: PCS

Sheet FR_VANNE_GUILLOTINE
D3: FICHE REFLEXE
B7: Site : | C7: ='N° Utiles'!$C$9 -> 0 | E7: Activité : | F7: ='N° Utiles'!$E$9 -> 0 | J7: MAJ le : | M7: ='N° Utiles'!$H$9 -> 0
B9: FERMETURE AUTOMATIQUE DE LA VANNE GUILLOTINE | M9: Page 1/3
C11: Scénario : Report d'alarme incendie sur le SSI- Feu avéré- Evacuation générale Risque de pollution-
C14: VANNE GUILLOTINE : FERMETURE
C16: Assistant OI
C17: Back-up Assistant OI
C19: ETAPES | E19: QUOI ? | J19: OU ? | M19: QUI ?
C20: 1 | E20: Contrôle visuel de la fermeture des vannes sur les boîtiers Orange clignotant => en cours de fermeture Orange fixe => vanne fermée | J20: PCS | M20: Assistant Opération Interne Personne désignée
C26: 2
E27: Contrôle physique de la fermeture des vannes sur les 3 zones. Lever la plaque et vérifier que la trappe est refermée | J27: VOIR PLAN | M27: Assistant Opération Interne Personne désignée
C32: 4
E33: Consigner l'évenement sur la main courante
J35: PCS
D47: FICHE REFLEXE
B51: Site : | C51: ='N° Utiles'!$C$9 -> 0 | E51: Activité : | F51: ='N° Utiles'!$E$9 -> 0 | J51: MAJ le : | M51: ='N° Utiles'!$H$9 -> 0
B53: FERMETURE SEMI-AUTOMATIQUE DE LA VANNE GUILLOTINE | M53: Page 2/3
C55: Scénario : Début d'incendie n'ayant pas déclenché le SSI- Risque de pollution-Heures ouvrées
C58: VANNE GUILLOTINE : FERMETURE
C60: Assistant OI
C61: Back-up Assistant OI
C63: ETAPES | E63: QUOI ? | J63: OU ? | M63: QUI ?
C64: 1 | E64: Procéder à la fermeture des vannes guillotines | J64: Poste de sécurité | M64: Assistant Opération Interne Personne désignée
C68: 2
E69: Appuyer sur les déclencheurs manuels des boitiers Ci-dessous 2 modèles différents | J69: VOIR PLAN | M69: Assistant Opération Interne Personne désignée
C74: 4
E75: Contrôle physique de la fermeture des vannes sur les 3 zones | M75: Assistant Opération Interne Personne désignée
J81: VOIR PLAN
C86: 5 | E86: Consigner l'évenement sur la main courante
J89: PCS | M89: Agent de sécurité
C92: 6
D107: FICHE REFLEXE
B111: Site : | C111: ='N° Utiles'!$C$9 -> 0 | E111: Activité : | F111: ='N° Utiles'!$E$9 -> 0 | J111: MAJ le : | M111: ='N° Utiles'!$H$9 -> 0
B113: FERMETURE MANUELLE DES VANNES | M113: Page 3/3
C115: Scénario : Coupure électrique. Le système de commande de fermeture des vannes est inopérant- Risque de pollution-Heures ouvrées
C118: VANNE GUILLOTINE : FERMETURE
C120: Assistant OI
C121: Back-up Assistant OI
C123: ETAPES | E123: QUOI ? | J123: OU ? | M123: QUI ?
C124: 1 | E124: Se rendre dans les zones pour fermeture manuelles des 3 vannes | J124: VOIR PLAN | M124: Assistant Opération Interne Personne désignée
...
