Workbook

Sheet Base
A1: Ref METRO | B1: MGB | C1: Libellé Article | D1: Secteur Activité | E1: Groupe Article | F1: Sous-groupe Article | G1: Format | H1: Déploiement National / Local | I1: FAMILLE | J1: Longueur | K1: Largeur | L1: Hauteur | M1: Volume | N1: Conditionnement Vente | O1: Conditionnement fournisseur | P1: Vendu au poids | Q1: CELLULE
A2: 242267 | B2: 835280001001 | C2: * MAYONAIS 970ML CALIFORN | D2: 51 - POLE SALE | E2: 396 - SAUCES FROIDES | F2: 20 - MAYONNAISE | G2: 30 - MAYONNAISE > 70% D HUILE | H2: DF1 | I2: SEC | J2: 8.3 | K2: 8.3 | L2: 28.5 | M2: 1963.365 | N2: 1 | O2: 6
A3: 307663 | B3: 895622001001 | C3: *AIL SEMOULE 1KG ARO | D3: 51 - POLE SALE | E3: 394 - ASSAISONNEMENTS | F3: 39420 - HERBES | G3: 3942045 - AIL | I3: SEC | N3: 1 | O3: 6 | P3: FALSE
A4: 247707 | B4: 840682001001 | C4: *CACAHUET GRILL 1,5KG MENG | D4: 52 - POLE SUCREE | E4: 401 - SNACKS SALES | F4: 10 - GRAINES | G4: 20 - CACAHUETES SALEES | H4: DF1 | I4: SEC | J4: 12 | K4: 8 | L4: 25 | M4: 2400 | N4: 1 | O4: 7 | P4: FALSE
A5: 247859 | B5: 840838001001 | C5: *CACAHUETE SALE 1,5KG MC | D5: 52 - POLE SUCREE | E5: 401 - SNACKS SALES | F5: 10 - GRAINES | G5: 20 - CACAHUETES SALEES | H5: DF1 | I5: TOP | J5: 22.5 | K5: 6 | L5: 33.5 | M5: 4522.5 | N5: 1 | O5: 6 | P5: FALSE
A6: 247770 | B6: 840753001001 | C6: *CHOC MILKA LAIT TB 100GX5 | D6: 52 - POLE SUCREE | E6: 402 - CHOCOLAT | F6: 10 - TABLETTES | G6: 20 - LAIT | H6: DF1 | I6: SEC | J6: 4 | K6: 8 | L6: 16 | M6: 512 | N6: 1 | O6: 30 | P6: FALSE
A7: 307677 | B7: 895635001001 | C7: *CUMIN MOULU 1KG ARO | D7: 51 - POLE SALE | E7: 394 - ASSAISONNEMENTS | F7: 30 - EPICES | G7: 11 - CUMIN | H7: DF1 | I7: SEC | N7: 1 | O7: 6 | P7: FALSE
A8: 12793 | B8: 212791001001 | C8: *ESCO SEL FIN SAC 25KG | D8: 51 - POLE SALE | E8: 394 - ASSAISONNEMENTS | F8: 10 - SEL | G8: 20 - SEL DE CUISINE | H8: DF1 | I8: SEC LOURD | J8: 34 | K8: 56 | L8: 12 | M8: 22848 | N8: 1 | O8: 1 | P8: FALSE
A9: 242188 | B9: 835170001002 | C9: *FARINE BLE T 55 1KG ARO | D9: 51 - POLE SALE | E9: 397 - FARINES | F9: 10 - FARINE DE BLE | G9: 05 - BLE TENDRE < 1KG | H9: DF1 | I9: SEC | J9: 39 | K9: 22 | L9: 17 | M9: 14586 | N9: 10 | O9: 10 | P9: FALSE
A10: 242203 | B10: 835185001002 | C10: *FARINE BLE T45 1KG ROC | D10: 51 - POLE SALE | E10: 397 - FARINES | F10: 10 - FARINE DE BLE | G10: 05 - BLE TENDRE < 1KG | H10: DF1 | I10: SEC | J10: 39 | K10: 22 | L10: 17 | M10: 14586 | N10: 10 | O10: 10 | P10: FALSE
A11: 242274 | B11: 835289001001 | C11: *KETCHUP 950ML CALIFORNIA | D11: 51 - POLE SALE | E11: 396 - SAUCES FROIDES | F11: 30 - KETCHUP | G11: 10 - KETCHUP | H11: DF1 | I11: SEC | J11: 8.3 | K11: 8.3 | L11: 28.5 | M11: 1963.365 | N11: 1 | O11: 6 | P11: FALSE
A12: 57605 | B12: 678011001001 | C12: *MC BOLETS ET CEPES 500GR | D12: 51 - POLE SALE | E12: 395 - CONDIMENTS SECHES | F12: 10 - CHAMPIGNONS SECS | G12: 30 - MELANGE DE CHAMPIGNONG | H12: DF1 | I12: SEC | J12: 13.4 | K12: 13.4 | L12: 24.3 | M12: 4363.308 | N12: 1 | O12: 6 | P12: FALSE
A13: 242281 | B13: 835300001001 | C13: *MC BP FARINE PATIS T45 10KG | D13: 51 - POLE SALE | E13: 397 - FARINES | F13: 40 - SPECIALE | G13: 40 - FARINE PATISSERIE | H13: DF1 | I13: SEC LOURD | J13: 15 | K13: 25 | L13: 44 | M13: 16500 | N13: 1 | O13: 1 | P13: FALSE
A14: 275539 | B14: 866457001001 | C14: *MC CEPES EXTRA TUBO 500G | D14: 51 - POLE SALE | E14: 395 - CONDIMENTS SECHES | F14: 10 - CHAMPIGNONS SECS | G14: 20 - BOLETUS | H14: DF1 | I14: SEC | J14: 13.5 | K14: 14 | L14: 24 | M14: 4536 | N14: 1 | O14: 6 | P14: FALSE
A15: 106008 | B15: 299847001001 | C15: *MC CONFIT CANARD 12 CUISS5/1 | D15: 51 - POLE SALE | E15: 369 - PLATS CUISINES EN CONSERVE | F15: 20 - VIANDES PREPAREES EN CONSERVE | G15: 10 - CONFIT | H15: DF1 | I15: SEC | J15: 15.3 | K15: 15.3 | L15: 24.6 | M15: 5758.614 | N15: 1 | O15: 2 | P15: FALSE
A16: 172362 | B16: 170153001001 | C16: *MC CONFIT GESIERS CANARD 4/4 | D16: 51 - POLE SALE | E16: 369 - PLATS CUISINES EN CONSERVE | F16: 20 - VIANDES PREPAREES EN CONSERVE | G16: 15 - GESIER | H16: DF1 | I16: SEC | J16: 9.9 | K16: 9.9 | L16: 11.8 | M16: 1156.518 | N16: 1 | O16: 6 | P16: FALSE
A17: 5116 | B17: 205114001001 | C17: *MC ESC. LUCO 4/4 12DZ MOYEN | D17: 51 - POLE SALE | E17: 368 - CONSERVE VIANDES/SAUCISSES | F17: 10 - VIANDE EN CONSERVE | G17: 50 - ESCARGOTS MEDIUM | H17: DF1 | I17: SEC | J17: 10 | K17: 10 | L17: 11.8 | M17: 1180 | N17: 1 | O17: 6 | P17: FALSE
A18: 5025 | B18: 205023001001 | C18: *MC ESC. POMA 4/4 10DZ B.GROS | D18: 51 - POLE SALE | E18: 368 - CONSERVE VIANDES/SAUCISSES | F18: 10 - VIANDE EN CONSERVE | G18: 55 - ESCARGOTS LARGE | H18: DF1 | I18: SEC | J18: 10 | K18: 10 | L18: 11.8 | M18: 1180 | N18: 1 | O18: 6 | P18: FALSE
A19: 5043 | B19: 205041001001 | C19: *MC ESC. POMA 4/4 12DZ MOYEN | D19: 51 - POLE SALE | E19: 368 - CONSERVE VIANDES/SAUCISSES | F19: 10 - VIANDE EN CONSERVE | G19: 50 - ESCARGOTS MEDIUM | H19: DF1 | I19: SEC | J19: 10 | K19: 10 | L19: 11.8 | M19: 1180 | N19: 1 | O19: 6
A20: 242279 | B20: 835297001001 | C20: *MC FARINE PANIF. T65 25KG | D20: 51 - POLE SALE | E20: 397 - FARINES | F20: 40 - SPECIALE | G20: 30 - FARINE BOULANGERIE | H20: DF1 | I20: SEC LOURD | J20: 35 | K20: 16 | L20: 70 | M20: 39200 | N20: 1 | O20: 1 | P20: FALSE
A21: 242175 | B21: 835154001002 | C21: *MC FARINE SARASIN 1KG | D21: 51 - POLE SALE | E21: 397 - FARINES | F21: 10 - FARINE DE BLE | G21: 55 - SARRASIN < 1KG | H21: DF1 | I21: SEC | J21: 40.1 | K21: 22.4 | L21: 16 | M21: 14371.84 | N21: 10 | O21: 10 | P21: FALSE
A22: 242282 | B22: 835301001001 | C22: *MC FARINE TTUSAG T55 10KG | D22: 51 - POLE SALE | E22: 397 - FARINES | F22: 10 - FARINE DE BLE | G22: 10 - BLE TENDRE > 1KG | H22: DF1 | I22: SEC LOURD | J22: 1.5 | K22: 2.4 | L22: 4.1 | M22: 14.76 | N22: 1 | O22: 1 | P22: FALSE
A23: 273564 | B23: 864458001001 | C23: *MC GARNITURE FOREST TUBO500G | D23: 51 - POLE SALE | E23: 395 - CONDIMENTS SECHES | F23: 10 - CHAMPIGNONS SECS | G23: 30 - MELANGE DE CHAMPIGNONG | H23: DF1 | I23: SEC | J23: 13.5 | K23: 14 | L23: 24 | M23: 4536 | N23: 1 | O23: 6 | P23: FALSE
A24: 172364 | B24: 170155001001 | C24: *MC GRAISSE DE CANARD 5/1 | D24: 51 - POLE SALE | E24: 369 - PLATS CUISINES EN CONSERVE | F24: 20 - VIANDES PREPAREES EN CONSERVE | G24: 25 - GRAISSE | H24: DF1 | I24: SEC | J24: 15.4 | K24: 15.4 | L24: 24.5 | M24: 5810.42 | N24: 1 | O24: 3 | P24: FALSE
A25: 175959 | B25: 173020001001 | C25: *MC MEL MEXICAIN POT 500GR | D25: 51 - POLE SALE | E25: 394 - ASSAISONNEMENTS | F25: 30 - EPICES | G25: 58 - MELANGE EPICES POUR VIANDE | H25: DF1 | I25: SEC | J25: 8.5 | K25: 8.5 | L25: 20 | M25: 1445 | N25: 1 | O25: 4 | P25: FALSE
A26: 63729 | B26: 635219001001 | C26: *MC MINI MORILLE SAUV TUBO500G | D26: 51 - POLE SALE | E26: 395 - CONDIMENTS SECHES | F26: 10 - CHAMPIGNONS SECS | G26: 60 - MORILLES | H26: DF1 | I26: SEC | N26: 1 | O26: 6 | P26: FALSE
A27: 212244 | B27: 806427001001 | C27: *MC MORILLE EXTRA SAU TUBO400G | D27: 51 - POLE SALE | E27: 395 - CONDIMENTS SECHES | F27: 10 - CHAMPIGNONS SECS | G27: 60 - MORILLES | H27: DF1 | I27: SEC | J27: 13.4 | K27: 13.4 | L27: 24.3 | M27: 4363.308 | N27: 1 | O27: 6 | P27: FALSE
A28: 4808 | B28: 685257001001 | C28: *MC MORILLE SAU JUMBO TUBO200G | D28: 51 - POLE SALE | E28: 395 - CONDIMENTS SECHES | F28: 10 - CHAMPIGNONS SECS | G28: 60 - MORILLES | H28: DF1 | I28: SEC | J28: 12 | K28: 12 | L28: 16 | M28: 2304 | N28: 1 | O28: 6 | P28: FALSE
A29: 212245 | B29: 806428001001 | C29: *MC MORILLE SAU SPECI TUBO400G | D29: 51 - POLE SALE | E29: 395 - CONDIMENTS SECHES | F29: 10 - CHAMPIGNONS SECS | G29: 60 - MORILLES | H29: DF1 | I29: SEC | J29: 13.4 | K29: 13.4 | L29: 24.3 | M29: 4363.308 | N29: 1 | O29: 6 | P29: FALSE
A30: 296912 | B30: 886101001001 | C30: *MC MORILLE TRAITEUR 400G | D30: 51 - POLE SALE | E30: 395 - CONDIMENTS SECHES | F30: 10 - CHAMPIGNONS SECS | G30: 60 - MORILLES | H30: DF1 | I30: SEC | N30: 1 | O30: 6 | P30: FALSE
A31: 40244 | B31: 676343001001 | C31: *MC QUEU MORILLE SAU TUBO500G | D31: 51 - POLE SALE | E31: 395 - CONDIMENTS SECHES | F31: 10 - CHAMPIGNONS SECS | G31: 60 - MORILLES | H31: DF1 | I31: SEC | J31: 13.4 | K31: 13.4 | L31: 24.3 | M31: 4363.308 | N31: 1 | O31: 6
A32: 307664 | B32: 895623001001 | C32: *ORIGAN ENTIER 500G ARO | D32: 51 - POLE SALE | E32: 394 - ASSAISONNEMENTS | F32: 20 - HERBES | G32: 60 - ORIGAN | H32: DF1 | I32: SEC | N32: 1 | O32: 10 | P32: FALSE
A33: 241654 | B33: 835513001001 | C33: *SEMOUL BLE DUR EXTRA FINE 5K | D33: 51 - POLE SALE | E33: 387 - GRAIN | F33: 10 - GRAINS/CEREALES | G33: 35 - GRAIN/BLE | H33: DF1 | I33: TOP | J33: 8 | K33: 17 | L33: 37 | M33: 5032 | N33: 1 | O33: 1 | P33: FALSE
A34: 241660 | B34: 835519001001 | C34: *SEMOUL BLE DUR MOYEN 5KG REN | D34: 51 - POLE SALE | E34: 387 - GRAIN | F34: 10 - GRAINS/CEREALES | G34: 35 - GRAIN/BLE | H34: DF1 | I34: SEC LOURD | J34: 8 | K34: 17 | L34: 37 | M34: 5032 | N34: 1 | O34: 1 | P34: FALSE
A35: 241658 | B35: 835517001001 | C35: *SEMOUL BLE EXTRA FIN 25KG | D35: 51 - POLE SALE | E35: 387 - GRAIN | F35: 10 - GRAINS/CEREALES | G35: 35 - GRAIN/BLE | H35: DF1 | I35: SEC LOURD | J35: 17 | K35: 38 | L35: 58 | M35: 37468 | N35: 1 | O35: 1 | P35: FALSE
A36: 241653 | B36: 835512001001 | C36: *SEMOUL BLE FIN 5KG RENARD | D36: 51 - POLE SALE | E36: 387 - GRAIN | F36: 10 - GRAINS/CEREALES | G36: 35 - GRAIN/BLE | H36: DF5 | I36: SEC LOURD | J36: 7 | K36: 18 | L36: 42 | M36: 5292 | N36: 1 | O36: 1 | P36: FALSE
A37: 241663 | B37: 835522001001 | C37: *SEMOUL PATES FRAICHE SAC 5K | D37: 51 - POLE SALE | E37: 397 - FARINES | F37: 40 - SPECIALE | G37: 20 - FARINE PATE | H37: DF1 | I37: SEC | J37: 11 | K37: 21 | L37: 40 | M37: 9240 | N37: 1 | O37: 1
A38: 71444 | B38: 71444001002 | C38: *SOLE 300/400 X6 P/ANE.SOLEA VULGARIS | D38: 61 - MAREE | E38: 342 - POISSONS DE MER ENTIERS | F38: 34209 - ATLANTIQUE NORD EST 27 | G38: 3420982 - SOLE | I38: Marée | N38: 1 | O38: 6 | P38: TRUE
A39: 247776 | B39: 840759001001 | C39: *SUCRE CRISTAL N2 BS SAC 25KG | D39: 52 - POLE SUCREE | E39: 382 - SUCRE ET EDULCORANT | F39: 10 - SUCRE BLANC | G39: 60 - SUCRE EN POUDRE > 1KG | H39: DF1 | I39: SEC LOURD | J39: 76 | K39: 38 | L39: 11.5 | M39: 33212 | N39: 1 | O39: 1 | P39: FALSE
A40: 247886 | B40: 840894001001 | C40: *SUCRE ENV AMBRE/BLANC 2,5KG | D40: 52 - POLE SUCREE | E40: 382 - SUCRE ET EDULCORANT | F40: 30 - SUCRE BRUN | G40: 10 - BRUN PORTION CUBES | H40: DF1 | I40: SEC | J40: 20 | K40: 20 | L40: 29 | M40: 11600 | N40: 1 | O40: 4 | P40: FALSE
...

Sheet Ref Unité VS Pack
A1: Ref METRO | B1: MGB | C1: Gauche | D1: Packaging | E1: Libellé Article | F1: Conditionnement Vente | G1: Conditionnement fournisseur | H1: Vendu au poids | I1: en stock ?
A2: 236386 | B2: 829930001001 | C2: =LEFT(B2,11) -> 82993000100 | D2: =RIGHT(B2,1) -> 1 | E2: AEROSOL SUCREE 250ML WHIPPY | F2: 1 | G2: 12 | H2: FALSE | I2: =COUNTIF(#REF!,'Ref Unité VS Pack'!B2) -> #REF!
A3: 236387 | B3: 829930001002 | C3: =LEFT(B3,11) -> 82993000100 | D3: =RIGHT(B3,1) -> 2 | E3: AEROSOL SUCREE 250ML WHIPPY | F3: 12 | G3: 12 | H3: FALSE | I3: =COUNTIF(#REF!,'Ref Unité VS Pack'!B3) -> #REF!
A4: 72233 | B4: 657496001001 | C4: =LEFT(B4,11) -> 65749600100 | D4: =RIGHT(B4,1) -> 1 | E4: AIGUILLETTE PLTHAL IQF 1KG UE | F4: 1 | G4: 4 | H4: FALSE | I4: =COUNTIF(#REF!,'Ref Unité VS Pack'!B4) -> #REF!
A5: 166664 | B5: 657496001002 | C5: =LEFT(B5,11) -> 65749600100 | D5: =RIGHT(B5,1) -> 2 | E5: AIGUILLETTE PLTHAL IQF 1KG UE | H5: FALSE | I5: =COUNTIF(#REF!,'Ref Unité VS Pack'!B5) -> #REF!
A6: 187191 | B6: 382099001001 | C6: =LEFT(B6,11) -> 38209900100 | D6: =RIGHT(B6,1) -> 1 | E6: ALLUMETTE FUM BOIS HETR 1KG MC | F6: 1 | G6: 6 | H6: FALSE | I6: =COUNTIF(#REF!,'Ref Unité VS Pack'!B6) -> #REF!
A7: 239431 | B7: 382099001002 | C7: =LEFT(B7,11) -> 38209900100 | D7: =RIGHT(B7,1) -> 2 | E7: ALLUMETTE FUM BOIS HETR 1KG MC | H7: FALSE | I7: =COUNTIF(#REF!,'Ref Unité VS Pack'!B7) -> #REF!
A8: 187181 | B8: 382090001001 | C8: =LEFT(B8,11) -> 38209000100 | D8: =RIGHT(B8,1) -> 1 | E8: ALLUMETTE NATURE 1KG MC | F8: 1 | G8: 6 | H8: FALSE | I8: =COUNTIF(#REF!,'Ref Unité VS Pack'!B8) -> #REF!
A9: 239436 | B9: 382090001002 | C9: =LEFT(B9,11) -> 38209000100 | D9: =RIGHT(B9,1) -> 2 | E9: ALLUMETTE NATURE 1KG MC | H9: FALSE | I9: =COUNTIF(#REF!,'Ref Unité VS Pack'!B9) -> #REF!
A10: 192596 | B10: 387559001001 | C10: =LEFT(B10,11) -> 38755900100 | D10: =RIGHT(B10,1) -> 1 | E10: AMERICANO DOB 16D 1L | F10: 1 | G10: 6 | H10: FALSE | I10: =COUNTIF(#REF!,'Ref Unité VS Pack'!B10) -> #REF!
A11: 210887 | B11: 387559001002 | C11: =LEFT(B11,11) -> 38755900100 | D11: =RIGHT(B11,1) -> 2 | E11: AMERICANO DOB 16D 1L | H11: FALSE | I11: =COUNTIF(#REF!,'Ref Unité VS Pack'!B11) -> #REF!
A12: 296129 | B12: 885385001001 | C12: =LEFT(B12,11) -> 88538500100 | D12: =RIGHT(B12,1) -> 1 | E12: APERITIVO DELAITRE 12,5D 1L | F12: 1 | G12: 6 | H12: FALSE | I12: =COUNTIF(#REF!,'Ref Unité VS Pack'!B12) -> #REF!
A13: 296479 | B13: 885385001002 | C13: =LEFT(B13,11) -> 88538500100 | D13: =RIGHT(B13,1) -> 2 | E13: APERITIVO DELAITRE 12,5D 1L | H13: FALSE | I13: =COUNTIF(#REF!,'Ref Unité VS Pack'!B13) -> #REF!
A14: 285097 | B14: 875505001001 | C14: =LEFT(B14,11) -> 87550500100 | D14: =RIGHT(B14,1) -> 1 | E14: APEROL 12,5D 1L | F14: 1 | G14: 6 | H14: FALSE | I14: =COUNTIF(#REF!,'Ref Unité VS Pack'!B14) -> #REF!
A15: 285189 | B15: 875505001002 | C15: =LEFT(B15,11) -> 87550500100 | D15: =RIGHT(B15,1) -> 2 | E15: APEROL 12,5D 1L | H15: FALSE | I15: =COUNTIF(#REF!,'Ref Unité VS Pack'!B15) -> #REF!
A16: 306258 | B16: 894297001001 | C16: =LEFT(B16,11) -> 89429700100 | D16: =RIGHT(B16,1) -> 1 | E16: ARO HLE COLZA 1L | F16: 1 | G16: 15 | H16: FALSE | I16: =COUNTIF(#REF!,'Ref Unité VS Pack'!B16) -> #REF!
A17: 184044 | B17: 894297001002 | C17: =LEFT(B17,11) -> 89429700100 | D17: =RIGHT(B17,1) -> 2 | E17: ARO HLE COLZA 1L | H17: FALSE | I17: =COUNTIF(#REF!,'Ref Unité VS Pack'!B17) -> #REF!
A18: 187405 | C18: =LEFT(B18,11) | D18: =RIGHT(B18,1) | E18: ARO PULPE DE TOMATE AU JUS 5/1 | H18: FALSE | I18: =COUNTIF(#REF!,'Ref Unité VS Pack'!B18) -> #REF!
A19: 762011 | C19: =LEFT(B19,11) | D19: =RIGHT(B19,1) | E19: AVO HASS FILET C.227/274G PC4 C1 IL ISRAEL | H19: FALSE | I19: =COUNTIF(#REF!,'Ref Unité VS Pack'!B19) -> #REF!
A20: 192676 | B20: 387642001001 | C20: =LEFT(B20,11) -> 38764200100 | D20: =RIGHT(B20,1) -> 1 | E20: BAILEYS IRISH CREME 17D 70CL | F20: 1 | G20: 6 | H20: FALSE | I20: =COUNTIF(#REF!,'Ref Unité VS Pack'!B20) -> #REF!
A21: 248051 | B21: 387642001002 | C21: =LEFT(B21,11) -> 38764200100 | D21: =RIGHT(B21,1) -> 2 | E21: BAILEYS IRISH CREME 17D 70CL | H21: FALSE | I21: =COUNTIF(#REF!,'Ref Unité VS Pack'!B21) -> #REF!
A22: 231272 | B22: 824733001001 | C22: =LEFT(B22,11) -> 82473300100 | D22: =RIGHT(B22,1) -> 1 | E22: BANDOL RSE GALETS 75CL MIL | F22: 1 | G22: 6 | H22: FALSE | I22: =COUNTIF(#REF!,'Ref Unité VS Pack'!B22) -> #REF!
A23: 231273 | B23: 824733001002 | C23: =LEFT(B23,11) -> 82473300100 | D23: =RIGHT(B23,1) -> 2 | E23: BANDOL RSE GALETS 75CL MIL | H23: FALSE | I23: =COUNTIF(#REF!,'Ref Unité VS Pack'!B23) -> #REF!
A24: 302035 | B24: 890989001001 | C24: =LEFT(B24,11) -> 89098900100 | D24: =RIGHT(B24,1) -> 1 | E24: BEAUSEJOUR HOST HT MED 75CL | F24: 1 | G24: 6 | H24: FALSE | I24: =COUNTIF(#REF!,'Ref Unité VS Pack'!B24) -> #REF!
A25: 302036 | B25: 890989001002 | C25: =LEFT(B25,11) -> 89098900100 | D25: =RIGHT(B25,1) -> 2 | E25: BEAUSEJOUR HOST HT MED 75CL | H25: FALSE | I25: =COUNTIF(#REF!,'Ref Unité VS Pack'!B25) -> #REF!
A26: 225209 | B26: 818750001001 | C26: =LEFT(B26,11) -> 81875000100 | D26: =RIGHT(B26,1) -> 1 | E26: BEURRE DS 500G MA PAYSANNE | F26: 1 | G26: 20 | H26: FALSE | I26: =COUNTIF(#REF!,'Ref Unité VS Pack'!B26) -> #REF!
A27: 264597 | B27: 818750001002 | C27: =LEFT(B27,11) -> 81875000100 | D27: =RIGHT(B27,1) -> 2 | E27: BEURRE DS 500G MA PAYSANNE | H27: FALSE | I27: =COUNTIF(#REF!,'Ref Unité VS Pack'!B27) -> #REF!
A28: 225210 | B28: 818751001001 | C28: =LEFT(B28,11) -> 81875100100 | D28: =RIGHT(B28,1) -> 1 | E28: BEURRE DX 500G MA PAYSANNE | F28: 1 | G28: 20 | H28: FALSE | I28: =COUNTIF(#REF!,'Ref Unité VS Pack'!B28) -> #REF!
A29: 264605 | B29: 818751001002 | C29: =LEFT(B29,11) -> 81875100100 | D29: =RIGHT(B29,1) -> 2 | E29: BEURRE DX 500G MA PAYSANNE | H29: FALSE | I29: =COUNTIF(#REF!,'Ref Unité VS Pack'!B29) -> #REF!
A30: 247852 | B30: 840832001001 | C30: =LEFT(B30,11) -> 84083200100 | D30: =RIGHT(B30,1) -> 1 | E30: BEURRE DX 500G PRESID.PROF | F30: 1 | G30: 20 | H30: FALSE | I30: =COUNTIF(#REF!,'Ref Unité VS Pack'!B30) -> #REF!
A31: 247853 | B31: 840832001002 | C31: =LEFT(B31,11) -> 84083200100 | D31: =RIGHT(B31,1) -> 2 | E31: BEURRE DX 500G PRESID.PROF | H31: FALSE | I31: =COUNTIF(#REF!,'Ref Unité VS Pack'!B31) -> #REF!
A32: 297475 | B32: 886562001001 | C32: =LEFT(B32,11) -> 88656200100 | D32: =RIGHT(B32,1) -> 1 | E32: BEURRE DX PLQ 500G METRO CHEF | F32: 1 | G32: 20 | H32: FALSE | I32: =COUNTIF(#REF!,'Ref Unité VS Pack'!B32) -> #REF!
A33: 298197 | B33: 886562001002 | C33: =LEFT(B33,11) -> 88656200100 | D33: =RIGHT(B33,1) -> 2 | E33: BEURRE DX PLQ 500G METRO CHEF | F33: 20 | G33: 20 | H33: FALSE | I33: =COUNTIF(#REF!,'Ref Unité VS Pack'!B33) -> #REF!
A34: 269860 | B34: 861758001001 | C34: =LEFT(B34,11) -> 86175800100 | D34: =RIGHT(B34,1) -> 1 | E34: BEURRE SEC TOUR COLORE 1KG FLD | F34: 1 | G34: 10 | H34: FALSE | I34: =COUNTIF(#REF!,'Ref Unité VS Pack'!B34) -> #REF!
A35: 269861 | B35: 861758001002 | C35: =LEFT(B35,11) -> 86175800100 | D35: =RIGHT(B35,1) -> 2 | E35: BEURRE SEC TOUR COLORE 1KG FLD | H35: FALSE | I35: =COUNTIF(#REF!,'Ref Unité VS Pack'!B35) -> #REF!
A36: 264559 | B36: 857405001001 | C36: =LEFT(B36,11) -> 85740500100 | D36: =RIGHT(B36,1) -> 1 | E36: BEURRE SEC TOURAGE 1KG FLECHAR | F36: 1 | G36: 10 | H36: FALSE | I36: =COUNTIF(#REF!,'Ref Unité VS Pack'!B36) -> #REF!
A37: 264560 | B37: 857405001002 | C37: =LEFT(B37,11) -> 85740500100 | D37: =RIGHT(B37,1) -> 2 | E37: BEURRE SEC TOURAGE 1KG FLECHAR | H37: FALSE | I37: =COUNTIF(#REF!,'Ref Unité VS Pack'!B37) -> #REF!
A38: 188501 | C38: =LEFT(B38,11) | D38: =RIGHT(B38,1) | E38: BOULE MACREUSE HAL UE | H38: TRUE | I38: =COUNTIF(#REF!,'Ref Unité VS Pack'!B38) -> #REF!
A39: 72251 | B39: 636897001001 | C39: =LEFT(B39,11) -> 63689700100 | D39: =RIGHT(B39,1) -> 1 | E39: BOULETTE A L'AGNEAU HALAL 1KG | F39: 1 | G39: 9 | I39: =COUNTIF(#REF!,'Ref Unité VS Pack'!B39) -> #REF!
A40: 166663 | B40: 636897001002 | C40: =LEFT(B40,11) -> 63689700100 | D40: =RIGHT(B40,1) -> 2 | E40: BOULETTE A L'AGNEAU HALAL 1KG | I40: =COUNTIF(#REF!,'Ref Unité VS Pack'!B40) -> #REF!
...
